Main() {
    try {
        #python
        raise Exception("Something went wrong")
        #endpython
    } catch (Error e) {
        Print: ("Caught error: " + e);
    }
}

